ERROR:Frugally:Exception on / [GET]
Traceback (most recent call last):
  File "/usr/local/lib/python3.6/dist-packages/flask/app.py", line 2447, in wsgi_app
    response = self.full_dispatch_request()
  File "/usr/local/lib/python3.6/dist-packages/flask/app.py", line 1952, in full_dispatch_request
    rv = self.handle_user_exception(e)
  File "/usr/local/lib/python3.6/dist-packages/flask/app.py", line 1821, in handle_user_exception
    reraise(exc_type, exc_value, tb)
  File "/usr/local/lib/python3.6/dist-packages/flask/_compat.py", line 39, in reraise
    raise value
  File "/usr/local/lib/python3.6/dist-packages/flask/app.py", line 1950, in full_dispatch_request
    rv = self.dispatch_request()
  File "/usr/local/lib/python3.6/dist-packages/flask/app.py", line 1936, in dispatch_request
    return self.view_functions[rule.endpoint](**req.view_args)
  File "/var/www/Frugally/Frugally/__init__.py", line 59, in index
    nike = getSQLNike()
  File "/var/www/Frugally/Frugally/__init__.py", line 488, in getSQLNike
    cursor.execute('SELECT * FROM NikeMen')
  File "/usr/local/lib/python3.6/dist-packages/mysql/connector/cursor_cext.py", line 233, in execute
    raise errors.ProgrammingError("Cursor is not connected")
mysql.connector.errors.ProgrammingError: Cursor is not connected
INFO:Frugally:Nordstrom objects loaded: 12499
INFO:Frugally:Nike objects loaded: 1512
INFO:Frugally:[['sort', 'discount'], ['vendors', 'all'], ['brands', 'all']]
INFO:Frugally:[['gender', 'men'], ['vendors', 'all'], ['brands', 'all']]
INFO:Frugally:men all all
ERROR:Frugally:Exception on /men/home [GET]
Traceback (most recent call last):
  File "/usr/local/lib/python3.6/dist-packages/flask/app.py", line 2447, in wsgi_app
    response = self.full_dispatch_request()
  File "/usr/local/lib/python3.6/dist-packages/flask/app.py", line 1952, in full_dispatch_request
    rv = self.handle_user_exception(e)
  File "/usr/local/lib/python3.6/dist-packages/flask/app.py", line 1821, in handle_user_exception
    reraise(exc_type, exc_value, tb)
  File "/usr/local/lib/python3.6/dist-packages/flask/_compat.py", line 39, in reraise
    raise value
  File "/usr/local/lib/python3.6/dist-packages/flask/app.py", line 1950, in full_dispatch_request
    rv = self.dispatch_request()
  File "/usr/local/lib/python3.6/dist-packages/flask/app.py", line 1936, in dispatch_request
    return self.view_functions[rule.endpoint](**req.view_args)
  File "/var/www/Frugally/Frugally/__init__.py", line 176, in men
    brands = getBrands(objects)
  File "/var/www/Frugally/Frugally/__init__.py", line 280, in getBrands
    if(i[3] not in brands):
TypeError: 'listing' object does not support indexing
INFO:Frugally:Nordstrom objects loaded: 12499
INFO:Frugally:Nike objects loaded: 1512
INFO:Frugally:[['sort', 'discount'], ['vendors', 'all'], ['brands', 'all']]
INFO:Frugally:[['gender', 'men'], ['vendors', 'all'], ['brands', 'all']]
INFO:Frugally:men all all
ERROR:Frugally:Exception on /men/home [GET]
Traceback (most recent call last):
  File "/usr/local/lib/python3.6/dist-packages/flask/app.py", line 2447, in wsgi_app
    response = self.full_dispatch_request()
  File "/usr/local/lib/python3.6/dist-packages/flask/app.py", line 1952, in full_dispatch_request
    rv = self.handle_user_exception(e)
  File "/usr/local/lib/python3.6/dist-packages/flask/app.py", line 1821, in handle_user_exception
    reraise(exc_type, exc_value, tb)
  File "/usr/local/lib/python3.6/dist-packages/flask/_compat.py", line 39, in reraise
    raise value
  File "/usr/local/lib/python3.6/dist-packages/flask/app.py", line 1950, in full_dispatch_request
    rv = self.dispatch_request()
  File "/usr/local/lib/python3.6/dist-packages/flask/app.py", line 1936, in dispatch_request
    return self.view_functions[rule.endpoint](**req.view_args)
  File "/var/www/Frugally/Frugally/__init__.py", line 176, in men
    brands = getBrands(objects)
  File "/var/www/Frugally/Frugally/__init__.py", line 280, in getBrands
    if(i[3] not in brands):
TypeError: 'listing' object does not support indexing
INFO:Frugally:Nordstrom objects loaded: 12499
INFO:Frugally:Nike objects loaded: 1512
INFO:Frugally:[['sort', 'discount'], ['vendors', 'all'], ['brands', 'all']]
INFO:Frugally:[['gender', 'men'], ['vendors', 'all'], ['brands', 'all']]
INFO:Frugally:men all all
ERROR:Frugally:Exception on /men/home [GET]
Traceback (most recent call last):
  File "/usr/local/lib/python3.6/dist-packages/flask/app.py", line 2447, in wsgi_app
    response = self.full_dispatch_request()
  File "/usr/local/lib/python3.6/dist-packages/flask/app.py", line 1952, in full_dispatch_request
    rv = self.handle_user_exception(e)
  File "/usr/local/lib/python3.6/dist-packages/flask/app.py", line 1821, in handle_user_exception
    reraise(exc_type, exc_value, tb)
  File "/usr/local/lib/python3.6/dist-packages/flask/_compat.py", line 39, in reraise
    raise value
  File "/usr/local/lib/python3.6/dist-packages/flask/app.py", line 1950, in full_dispatch_request
    rv = self.dispatch_request()
  File "/usr/local/lib/python3.6/dist-packages/flask/app.py", line 1936, in dispatch_request
    return self.view_functions[rule.endpoint](**req.view_args)
  File "/var/www/Frugally/Frugally/__init__.py", line 176, in men
    brands = getBrands(objects)
  File "/var/www/Frugally/Frugally/__init__.py", line 280, in getBrands
    if(i[3] not in brands):
TypeError: 'listing' object does not support indexing
INFO:Frugally:Nordstrom objects loaded: 12499
INFO:Frugally:Nike objects loaded: 1512
INFO:Frugally:[['sort', 'discount'], ['vendors', 'all'], ['brands', 'all']]
INFO:Frugally:[['gender', 'men'], ['vendors', 'all'], ['brands', 'all']]
INFO:Frugally:men all all
ERROR:Frugally:Exception on /men/home [GET]
Traceback (most recent call last):
  File "/usr/local/lib/python3.6/dist-packages/flask/app.py", line 2447, in wsgi_app
    response = self.full_dispatch_request()
  File "/usr/local/lib/python3.6/dist-packages/flask/app.py", line 1952, in full_dispatch_request
    rv = self.handle_user_exception(e)
  File "/usr/local/lib/python3.6/dist-packages/flask/app.py", line 1821, in handle_user_exception
    reraise(exc_type, exc_value, tb)
  File "/usr/local/lib/python3.6/dist-packages/flask/_compat.py", line 39, in reraise
    raise value
  File "/usr/local/lib/python3.6/dist-packages/flask/app.py", line 1950, in full_dispatch_request
    rv = self.dispatch_request()
  File "/usr/local/lib/python3.6/dist-packages/flask/app.py", line 1936, in dispatch_request
    return self.view_functions[rule.endpoint](**req.view_args)
  File "/var/www/Frugally/Frugally/__init__.py", line 176, in men
    brands = getBrands(objects)
  File "/var/www/Frugally/Frugally/__init__.py", line 280, in getBrands
    if(i[3] not in brands):
TypeError: 'listing' object does not support indexing
INFO:Frugally:Nordstrom objects loaded: 12499
INFO:Frugally:Nike objects loaded: 1512
INFO:Frugally:[['sort', 'discount'], ['vendors', 'all'], ['brands', 'all']]
INFO:Frugally:[['gender', 'women'], ['vendors', 'all'], ['brands', 'all']]
INFO:Frugally:women all all
ERROR:Frugally:Exception on /women/home [GET]
Traceback (most recent call last):
  File "/usr/local/lib/python3.6/dist-packages/flask/app.py", line 2447, in wsgi_app
    response = self.full_dispatch_request()
  File "/usr/local/lib/python3.6/dist-packages/flask/app.py", line 1952, in full_dispatch_request
    rv = self.handle_user_exception(e)
  File "/usr/local/lib/python3.6/dist-packages/flask/app.py", line 1821, in handle_user_exception
    reraise(exc_type, exc_value, tb)
  File "/usr/local/lib/python3.6/dist-packages/flask/_compat.py", line 39, in reraise
    raise value
  File "/usr/local/lib/python3.6/dist-packages/flask/app.py", line 1950, in full_dispatch_request
    rv = self.dispatch_request()
  File "/usr/local/lib/python3.6/dist-packages/flask/app.py", line 1936, in dispatch_request
    return self.view_functions[rule.endpoint](**req.view_args)
  File "/var/www/Frugally/Frugally/__init__.py", line 218, in women
    brands = getBrands(objects)
  File "/var/www/Frugally/Frugally/__init__.py", line 282, in getBrands
    if(i[3] not in brands):
TypeError: 'listing' object does not support indexing
ERROR:Frugally:Exception on /men/home [GET]
Traceback (most recent call last):
  File "/usr/local/lib/python3.6/dist-packages/flask/app.py", line 2447, in wsgi_app
    response = self.full_dispatch_request()
  File "/usr/local/lib/python3.6/dist-packages/flask/app.py", line 1952, in full_dispatch_request
    rv = self.handle_user_exception(e)
  File "/usr/local/lib/python3.6/dist-packages/flask/app.py", line 1821, in handle_user_exception
    reraise(exc_type, exc_value, tb)
  File "/usr/local/lib/python3.6/dist-packages/flask/_compat.py", line 39, in reraise
    raise value
  File "/usr/local/lib/python3.6/dist-packages/flask/app.py", line 1950, in full_dispatch_request
    rv = self.dispatch_request()
  File "/usr/local/lib/python3.6/dist-packages/flask/app.py", line 1936, in dispatch_request
    return self.view_functions[rule.endpoint](**req.view_args)
  File "/var/www/Frugally/Frugally/__init__.py", line 175, in men
    items = len(objects)
NameError: name 'objects' is not defined
ERROR:Frugally:Exception on / [GET]
Traceback (most recent call last):
  File "/usr/local/lib/python3.6/dist-packages/mysql/connector/connection_cext.py", line 489, in cmd_query
    raw_as_string=raw_as_string)
_mysql_connector.MySQLInterfaceError: MySQL server has gone away

During handling of the above exception, another exception occurred:

Traceback (most recent call last):
  File "/usr/local/lib/python3.6/dist-packages/flask/app.py", line 2447, in wsgi_app
    response = self.full_dispatch_request()
  File "/usr/local/lib/python3.6/dist-packages/flask/app.py", line 1952, in full_dispatch_request
    rv = self.handle_user_exception(e)
  File "/usr/local/lib/python3.6/dist-packages/flask/app.py", line 1821, in handle_user_exception
    reraise(exc_type, exc_value, tb)
  File "/usr/local/lib/python3.6/dist-packages/flask/_compat.py", line 39, in reraise
    raise value
  File "/usr/local/lib/python3.6/dist-packages/flask/app.py", line 1950, in full_dispatch_request
    rv = self.dispatch_request()
  File "/usr/local/lib/python3.6/dist-packages/flask/app.py", line 1936, in dispatch_request
    return self.view_functions[rule.endpoint](**req.view_args)
  File "/var/www/Frugally/Frugally/__init__.py", line 56, in index
    nordstrom = getSQLNordstrom()
  File "/var/www/Frugally/Frugally/__init__.py", line 491, in getSQLNordstrom
    cursor.execute('SELECT * FROM NordstromRackMen')
  File "/usr/local/lib/python3.6/dist-packages/mysql/connector/cursor_cext.py", line 266, in execute
    raw_as_string=self._raw_as_string)
  File "/usr/local/lib/python3.6/dist-packages/mysql/connector/connection_cext.py", line 492, in cmd_query
    sqlstate=exc.sqlstate)
mysql.connector.errors.DatabaseError: 2006 (HY000): MySQL server has gone away
ERROR:Frugally:Exception on / [GET]
Traceback (most recent call last):
  File "/usr/local/lib/python3.6/dist-packages/flask/app.py", line 2447, in wsgi_app
    response = self.full_dispatch_request()
  File "/usr/local/lib/python3.6/dist-packages/flask/app.py", line 1952, in full_dispatch_request
    rv = self.handle_user_exception(e)
  File "/usr/local/lib/python3.6/dist-packages/flask/app.py", line 1821, in handle_user_exception
    reraise(exc_type, exc_value, tb)
  File "/usr/local/lib/python3.6/dist-packages/flask/_compat.py", line 39, in reraise
    raise value
  File "/usr/local/lib/python3.6/dist-packages/flask/app.py", line 1950, in full_dispatch_request
    rv = self.dispatch_request()
  File "/usr/local/lib/python3.6/dist-packages/flask/app.py", line 1936, in dispatch_request
    return self.view_functions[rule.endpoint](**req.view_args)
  File "/var/www/Frugally/Frugally/__init__.py", line 56, in index
    nordstrom = getSQLNordstrom()
  File "/var/www/Frugally/Frugally/__init__.py", line 490, in getSQLNordstrom
    cursor = conn.cursor()
  File "/usr/local/lib/python3.6/dist-packages/mysql/connector/connection_cext.py", line 541, in cursor
    raise errors.OperationalError("MySQL Connection not available.")
mysql.connector.errors.OperationalError: MySQL Connection not available.
ERROR:Frugally:Exception on / [GET]
Traceback (most recent call last):
  File "/usr/local/lib/python3.6/dist-packages/mysql/connector/connection_cext.py", line 489, in cmd_query
    raw_as_string=raw_as_string)
_mysql_connector.MySQLInterfaceError: MySQL server has gone away

During handling of the above exception, another exception occurred:

Traceback (most recent call last):
  File "/usr/local/lib/python3.6/dist-packages/flask/app.py", line 2447, in wsgi_app
    response = self.full_dispatch_request()
  File "/usr/local/lib/python3.6/dist-packages/flask/app.py", line 1952, in full_dispatch_request
    rv = self.handle_user_exception(e)
  File "/usr/local/lib/python3.6/dist-packages/flask/app.py", line 1821, in handle_user_exception
    reraise(exc_type, exc_value, tb)
  File "/usr/local/lib/python3.6/dist-packages/flask/_compat.py", line 39, in reraise
    raise value
  File "/usr/local/lib/python3.6/dist-packages/flask/app.py", line 1950, in full_dispatch_request
    rv = self.dispatch_request()
  File "/usr/local/lib/python3.6/dist-packages/flask/app.py", line 1936, in dispatch_request
    return self.view_functions[rule.endpoint](**req.view_args)
  File "/var/www/Frugally/Frugally/__init__.py", line 58, in index
    nike = getSQLNike()
  File "/var/www/Frugally/Frugally/__init__.py", line 513, in getSQLNike
    cursor.execute('SELECT * FROM NikeWomen')
  File "/usr/local/lib/python3.6/dist-packages/mysql/connector/cursor_cext.py", line 266, in execute
    raw_as_string=self._raw_as_string)
  File "/usr/local/lib/python3.6/dist-packages/mysql/connector/connection_cext.py", line 492, in cmd_query
    sqlstate=exc.sqlstate)
mysql.connector.errors.DatabaseError: 2006 (HY000): MySQL server has gone away
ERROR:Frugally:Exception on / [GET]
Traceback (most recent call last):
  File "/usr/local/lib/python3.6/dist-packages/flask/app.py", line 2447, in wsgi_app
    response = self.full_dispatch_request()
  File "/usr/local/lib/python3.6/dist-packages/flask/app.py", line 1952, in full_dispatch_request
    rv = self.handle_user_exception(e)
  File "/usr/local/lib/python3.6/dist-packages/flask/app.py", line 1821, in handle_user_exception
    reraise(exc_type, exc_value, tb)
  File "/usr/local/lib/python3.6/dist-packages/flask/_compat.py", line 39, in reraise
    raise value
  File "/usr/local/lib/python3.6/dist-packages/flask/app.py", line 1950, in full_dispatch_request
    rv = self.dispatch_request()
  File "/usr/local/lib/python3.6/dist-packages/flask/app.py", line 1936, in dispatch_request
    return self.view_functions[rule.endpoint](**req.view_args)
  File "/var/www/Frugally/Frugally/__init__.py", line 56, in index
    nordstrom = getSQLNordstrom()
  File "/var/www/Frugally/Frugally/__init__.py", line 490, in getSQLNordstrom
    cursor = conn.cursor()
  File "/usr/local/lib/python3.6/dist-packages/mysql/connector/connection_cext.py", line 541, in cursor
    raise errors.OperationalError("MySQL Connection not available.")
mysql.connector.errors.OperationalError: MySQL Connection not available.
ERROR:Frugally:Exception on / [GET]
Traceback (most recent call last):
  File "/usr/local/lib/python3.6/dist-packages/flask/app.py", line 2447, in wsgi_app
    response = self.full_dispatch_request()
  File "/usr/local/lib/python3.6/dist-packages/flask/app.py", line 1952, in full_dispatch_request
    rv = self.handle_user_exception(e)
  File "/usr/local/lib/python3.6/dist-packages/flask/app.py", line 1821, in handle_user_exception
    reraise(exc_type, exc_value, tb)
  File "/usr/local/lib/python3.6/dist-packages/flask/_compat.py", line 39, in reraise
    raise value
  File "/usr/local/lib/python3.6/dist-packages/flask/app.py", line 1950, in full_dispatch_request
    rv = self.dispatch_request()
  File "/usr/local/lib/python3.6/dist-packages/flask/app.py", line 1936, in dispatch_request
    return self.view_functions[rule.endpoint](**req.view_args)
  File "/var/www/Frugally/Frugally/__init__.py", line 56, in index
    nordstrom = getSQLNordstrom()
  File "/var/www/Frugally/Frugally/__init__.py", line 490, in getSQLNordstrom
    cursor = conn.cursor()
  File "/usr/local/lib/python3.6/dist-packages/mysql/connector/connection_cext.py", line 541, in cursor
    raise errors.OperationalError("MySQL Connection not available.")
mysql.connector.errors.OperationalError: MySQL Connection not available.
ERROR:Frugally:Exception on / [GET]
Traceback (most recent call last):
  File "/usr/local/lib/python3.6/dist-packages/flask/app.py", line 2447, in wsgi_app
    response = self.full_dispatch_request()
  File "/usr/local/lib/python3.6/dist-packages/flask/app.py", line 1952, in full_dispatch_request
    rv = self.handle_user_exception(e)
  File "/usr/local/lib/python3.6/dist-packages/flask/app.py", line 1821, in handle_user_exception
    reraise(exc_type, exc_value, tb)
  File "/usr/local/lib/python3.6/dist-packages/flask/_compat.py", line 39, in reraise
    raise value
  File "/usr/local/lib/python3.6/dist-packages/flask/app.py", line 1950, in full_dispatch_request
    rv = self.dispatch_request()
  File "/usr/local/lib/python3.6/dist-packages/flask/app.py", line 1936, in dispatch_request
    return self.view_functions[rule.endpoint](**req.view_args)
  File "/var/www/Frugally/Frugally/__init__.py", line 56, in index
    nordstrom = getSQLNordstrom()
  File "/var/www/Frugally/Frugally/__init__.py", line 490, in getSQLNordstrom
    cursor = conn.cursor()
  File "/usr/local/lib/python3.6/dist-packages/mysql/connector/connection_cext.py", line 541, in cursor
    raise errors.OperationalError("MySQL Connection not available.")
mysql.connector.errors.OperationalError: MySQL Connection not available.
ERROR:Frugally:Exception on / [GET]
Traceback (most recent call last):
  File "/usr/local/lib/python3.6/dist-packages/flask/app.py", line 2447, in wsgi_app
    response = self.full_dispatch_request()
  File "/usr/local/lib/python3.6/dist-packages/flask/app.py", line 1952, in full_dispatch_request
    rv = self.handle_user_exception(e)
  File "/usr/local/lib/python3.6/dist-packages/flask/app.py", line 1821, in handle_user_exception
    reraise(exc_type, exc_value, tb)
  File "/usr/local/lib/python3.6/dist-packages/flask/_compat.py", line 39, in reraise
    raise value
  File "/usr/local/lib/python3.6/dist-packages/flask/app.py", line 1950, in full_dispatch_request
    rv = self.dispatch_request()
  File "/usr/local/lib/python3.6/dist-packages/flask/app.py", line 1936, in dispatch_request
    return self.view_functions[rule.endpoint](**req.view_args)
  File "/var/www/Frugally/Frugally/__init__.py", line 56, in index
    nordstrom = getSQLNordstrom()
  File "/var/www/Frugally/Frugally/__init__.py", line 490, in getSQLNordstrom
    cursor = conn.cursor()
  File "/usr/local/lib/python3.6/dist-packages/mysql/connector/connection_cext.py", line 541, in cursor
    raise errors.OperationalError("MySQL Connection not available.")
mysql.connector.errors.OperationalError: MySQL Connection not available.
ERROR:Frugally:Exception on / [GET]
Traceback (most recent call last):
  File "/usr/local/lib/python3.6/dist-packages/flask/app.py", line 2447, in wsgi_app
    response = self.full_dispatch_request()
  File "/usr/local/lib/python3.6/dist-packages/flask/app.py", line 1952, in full_dispatch_request
    rv = self.handle_user_exception(e)
  File "/usr/local/lib/python3.6/dist-packages/flask/app.py", line 1821, in handle_user_exception
    reraise(exc_type, exc_value, tb)
  File "/usr/local/lib/python3.6/dist-packages/flask/_compat.py", line 39, in reraise
    raise value
  File "/usr/local/lib/python3.6/dist-packages/flask/app.py", line 1950, in full_dispatch_request
    rv = self.dispatch_request()
  File "/usr/local/lib/python3.6/dist-packages/flask/app.py", line 1936, in dispatch_request
    return self.view_functions[rule.endpoint](**req.view_args)
  File "/var/www/Frugally/Frugally/__init__.py", line 56, in index
    nordstrom = getSQLNordstrom()
  File "/var/www/Frugally/Frugally/__init__.py", line 490, in getSQLNordstrom
    cursor = conn.cursor()
  File "/usr/local/lib/python3.6/dist-packages/mysql/connector/connection_cext.py", line 541, in cursor
    raise errors.OperationalError("MySQL Connection not available.")
mysql.connector.errors.OperationalError: MySQL Connection not available.
ERROR:Frugally:Exception on / [GET]
Traceback (most recent call last):
  File "/usr/local/lib/python3.6/dist-packages/flask/app.py", line 2447, in wsgi_app
    response = self.full_dispatch_request()
  File "/usr/local/lib/python3.6/dist-packages/flask/app.py", line 1952, in full_dispatch_request
    rv = self.handle_user_exception(e)
  File "/usr/local/lib/python3.6/dist-packages/flask/app.py", line 1821, in handle_user_exception
    reraise(exc_type, exc_value, tb)
  File "/usr/local/lib/python3.6/dist-packages/flask/_compat.py", line 39, in reraise
    raise value
  File "/usr/local/lib/python3.6/dist-packages/flask/app.py", line 1950, in full_dispatch_request
    rv = self.dispatch_request()
  File "/usr/local/lib/python3.6/dist-packages/flask/app.py", line 1936, in dispatch_request
    return self.view_functions[rule.endpoint](**req.view_args)
  File "/var/www/Frugally/Frugally/__init__.py", line 56, in index
    nordstrom = getSQLNordstrom()
  File "/var/www/Frugally/Frugally/__init__.py", line 490, in getSQLNordstrom
    cursor = conn.cursor()
  File "/usr/local/lib/python3.6/dist-packages/mysql/connector/connection_cext.py", line 541, in cursor
    raise errors.OperationalError("MySQL Connection not available.")
mysql.connector.errors.OperationalError: MySQL Connection not available.
ERROR:Frugally:Exception on / [GET]
Traceback (most recent call last):
  File "/usr/local/lib/python3.6/dist-packages/flask/app.py", line 2447, in wsgi_app
    response = self.full_dispatch_request()
  File "/usr/local/lib/python3.6/dist-packages/flask/app.py", line 1952, in full_dispatch_request
    rv = self.handle_user_exception(e)
  File "/usr/local/lib/python3.6/dist-packages/flask/app.py", line 1821, in handle_user_exception
    reraise(exc_type, exc_value, tb)
  File "/usr/local/lib/python3.6/dist-packages/flask/_compat.py", line 39, in reraise
    raise value
  File "/usr/local/lib/python3.6/dist-packages/flask/app.py", line 1950, in full_dispatch_request
    rv = self.dispatch_request()
  File "/usr/local/lib/python3.6/dist-packages/flask/app.py", line 1936, in dispatch_request
    return self.view_functions[rule.endpoint](**req.view_args)
  File "/var/www/Frugally/Frugally/__init__.py", line 56, in index
    nordstrom = getSQLNordstrom()
  File "/var/www/Frugally/Frugally/__init__.py", line 490, in getSQLNordstrom
    cursor = conn.cursor()
  File "/usr/local/lib/python3.6/dist-packages/mysql/connector/connection_cext.py", line 541, in cursor
    raise errors.OperationalError("MySQL Connection not available.")
mysql.connector.errors.OperationalError: MySQL Connection not available.
ERROR:Frugally:Exception on / [GET]
Traceback (most recent call last):
  File "/usr/local/lib/python3.6/dist-packages/flask/app.py", line 2447, in wsgi_app
    response = self.full_dispatch_request()
  File "/usr/local/lib/python3.6/dist-packages/flask/app.py", line 1952, in full_dispatch_request
    rv = self.handle_user_exception(e)
  File "/usr/local/lib/python3.6/dist-packages/flask/app.py", line 1821, in handle_user_exception
    reraise(exc_type, exc_value, tb)
  File "/usr/local/lib/python3.6/dist-packages/flask/_compat.py", line 39, in reraise
    raise value
  File "/usr/local/lib/python3.6/dist-packages/flask/app.py", line 1950, in full_dispatch_request
    rv = self.dispatch_request()
  File "/usr/local/lib/python3.6/dist-packages/flask/app.py", line 1936, in dispatch_request
    return self.view_functions[rule.endpoint](**req.view_args)
  File "/var/www/Frugally/Frugally/__init__.py", line 56, in index
    nordstrom = getSQLNordstrom()
  File "/var/www/Frugally/Frugally/__init__.py", line 490, in getSQLNordstrom
    cursor = conn.cursor()
  File "/usr/local/lib/python3.6/dist-packages/mysql/connector/connection_cext.py", line 541, in cursor
    raise errors.OperationalError("MySQL Connection not available.")
mysql.connector.errors.OperationalError: MySQL Connection not available.
ERROR:Frugally:Exception on / [GET]
Traceback (most recent call last):
  File "/usr/local/lib/python3.6/dist-packages/flask/app.py", line 2447, in wsgi_app
    response = self.full_dispatch_request()
  File "/usr/local/lib/python3.6/dist-packages/flask/app.py", line 1952, in full_dispatch_request
    rv = self.handle_user_exception(e)
  File "/usr/local/lib/python3.6/dist-packages/flask/app.py", line 1821, in handle_user_exception
    reraise(exc_type, exc_value, tb)
  File "/usr/local/lib/python3.6/dist-packages/flask/_compat.py", line 39, in reraise
    raise value
  File "/usr/local/lib/python3.6/dist-packages/flask/app.py", line 1950, in full_dispatch_request
    rv = self.dispatch_request()
  File "/usr/local/lib/python3.6/dist-packages/flask/app.py", line 1936, in dispatch_request
    return self.view_functions[rule.endpoint](**req.view_args)
  File "/var/www/Frugally/Frugally/__init__.py", line 56, in index
    nordstrom = getSQLNordstrom()
  File "/var/www/Frugally/Frugally/__init__.py", line 490, in getSQLNordstrom
    cursor = conn.cursor()
  File "/usr/local/lib/python3.6/dist-packages/mysql/connector/connection_cext.py", line 541, in cursor
    raise errors.OperationalError("MySQL Connection not available.")
mysql.connector.errors.OperationalError: MySQL Connection not available.
ERROR:Frugally:Exception on / [GET]
Traceback (most recent call last):
  File "/usr/local/lib/python3.6/dist-packages/flask/app.py", line 2447, in wsgi_app
    response = self.full_dispatch_request()
  File "/usr/local/lib/python3.6/dist-packages/flask/app.py", line 1952, in full_dispatch_request
    rv = self.handle_user_exception(e)
  File "/usr/local/lib/python3.6/dist-packages/flask/app.py", line 1821, in handle_user_exception
    reraise(exc_type, exc_value, tb)
  File "/usr/local/lib/python3.6/dist-packages/flask/_compat.py", line 39, in reraise
    raise value
  File "/usr/local/lib/python3.6/dist-packages/flask/app.py", line 1950, in full_dispatch_request
    rv = self.dispatch_request()
  File "/usr/local/lib/python3.6/dist-packages/flask/app.py", line 1936, in dispatch_request
    return self.view_functions[rule.endpoint](**req.view_args)
  File "/var/www/Frugally/Frugally/__init__.py", line 56, in index
    nordstrom = getSQLNordstrom()
  File "/var/www/Frugally/Frugally/__init__.py", line 490, in getSQLNordstrom
    cursor = conn.cursor()
  File "/usr/local/lib/python3.6/dist-packages/mysql/connector/connection_cext.py", line 541, in cursor
    raise errors.OperationalError("MySQL Connection not available.")
mysql.connector.errors.OperationalError: MySQL Connection not available.
ERROR:Frugally:Exception on / [GET]
Traceback (most recent call last):
  File "/usr/local/lib/python3.6/dist-packages/flask/app.py", line 2447, in wsgi_app
    response = self.full_dispatch_request()
  File "/usr/local/lib/python3.6/dist-packages/flask/app.py", line 1952, in full_dispatch_request
    rv = self.handle_user_exception(e)
  File "/usr/local/lib/python3.6/dist-packages/flask/app.py", line 1821, in handle_user_exception
    reraise(exc_type, exc_value, tb)
  File "/usr/local/lib/python3.6/dist-packages/flask/_compat.py", line 39, in reraise
    raise value
  File "/usr/local/lib/python3.6/dist-packages/flask/app.py", line 1950, in full_dispatch_request
    rv = self.dispatch_request()
  File "/usr/local/lib/python3.6/dist-packages/flask/app.py", line 1936, in dispatch_request
    return self.view_functions[rule.endpoint](**req.view_args)
  File "/var/www/Frugally/Frugally/__init__.py", line 56, in index
    nordstrom = getSQLNordstrom()
  File "/var/www/Frugally/Frugally/__init__.py", line 490, in getSQLNordstrom
    cursor = conn.cursor()
  File "/usr/local/lib/python3.6/dist-packages/mysql/connector/connection_cext.py", line 541, in cursor
    raise errors.OperationalError("MySQL Connection not available.")
mysql.connector.errors.OperationalError: MySQL Connection not available.
ERROR:Frugally:Exception on / [GET]
Traceback (most recent call last):
  File "/usr/local/lib/python3.6/dist-packages/flask/app.py", line 2447, in wsgi_app
    response = self.full_dispatch_request()
  File "/usr/local/lib/python3.6/dist-packages/flask/app.py", line 1952, in full_dispatch_request
    rv = self.handle_user_exception(e)
  File "/usr/local/lib/python3.6/dist-packages/flask/app.py", line 1821, in handle_user_exception
    reraise(exc_type, exc_value, tb)
  File "/usr/local/lib/python3.6/dist-packages/flask/_compat.py", line 39, in reraise
    raise value
  File "/usr/local/lib/python3.6/dist-packages/flask/app.py", line 1950, in full_dispatch_request
    rv = self.dispatch_request()
  File "/usr/local/lib/python3.6/dist-packages/flask/app.py", line 1936, in dispatch_request
    return self.view_functions[rule.endpoint](**req.view_args)
  File "/var/www/Frugally/Frugally/__init__.py", line 56, in index
    nordstrom = getSQLNordstrom()
  File "/var/www/Frugally/Frugally/__init__.py", line 490, in getSQLNordstrom
    cursor = conn.cursor()
  File "/usr/local/lib/python3.6/dist-packages/mysql/connector/connection_cext.py", line 541, in cursor
    raise errors.OperationalError("MySQL Connection not available.")
mysql.connector.errors.OperationalError: MySQL Connection not available.
ERROR:Frugally:Exception on / [GET]
Traceback (most recent call last):
  File "/usr/local/lib/python3.6/dist-packages/flask/app.py", line 2447, in wsgi_app
    response = self.full_dispatch_request()
  File "/usr/local/lib/python3.6/dist-packages/flask/app.py", line 1952, in full_dispatch_request
    rv = self.handle_user_exception(e)
  File "/usr/local/lib/python3.6/dist-packages/flask/app.py", line 1821, in handle_user_exception
    reraise(exc_type, exc_value, tb)
  File "/usr/local/lib/python3.6/dist-packages/flask/_compat.py", line 39, in reraise
    raise value
  File "/usr/local/lib/python3.6/dist-packages/flask/app.py", line 1950, in full_dispatch_request
    rv = self.dispatch_request()
  File "/usr/local/lib/python3.6/dist-packages/flask/app.py", line 1936, in dispatch_request
    return self.view_functions[rule.endpoint](**req.view_args)
  File "/var/www/Frugally/Frugally/__init__.py", line 56, in index
    nordstrom = getSQLNordstrom()
  File "/var/www/Frugally/Frugally/__init__.py", line 490, in getSQLNordstrom
    cursor = conn.cursor()
  File "/usr/local/lib/python3.6/dist-packages/mysql/connector/connection_cext.py", line 541, in cursor
    raise errors.OperationalError("MySQL Connection not available.")
mysql.connector.errors.OperationalError: MySQL Connection not available.
ERROR:Frugally:Exception on / [GET]
Traceback (most recent call last):
  File "/usr/local/lib/python3.6/dist-packages/flask/app.py", line 2447, in wsgi_app
    response = self.full_dispatch_request()
  File "/usr/local/lib/python3.6/dist-packages/flask/app.py", line 1952, in full_dispatch_request
    rv = self.handle_user_exception(e)
  File "/usr/local/lib/python3.6/dist-packages/flask/app.py", line 1821, in handle_user_exception
    reraise(exc_type, exc_value, tb)
  File "/usr/local/lib/python3.6/dist-packages/flask/_compat.py", line 39, in reraise
    raise value
  File "/usr/local/lib/python3.6/dist-packages/flask/app.py", line 1950, in full_dispatch_request
    rv = self.dispatch_request()
  File "/usr/local/lib/python3.6/dist-packages/flask/app.py", line 1936, in dispatch_request
    return self.view_functions[rule.endpoint](**req.view_args)
  File "/var/www/Frugally/Frugally/__init__.py", line 56, in index
    nordstrom = getSQLNordstrom()
  File "/var/www/Frugally/Frugally/__init__.py", line 490, in getSQLNordstrom
    cursor = conn.cursor()
  File "/usr/local/lib/python3.6/dist-packages/mysql/connector/connection_cext.py", line 541, in cursor
    raise errors.OperationalError("MySQL Connection not available.")
mysql.connector.errors.OperationalError: MySQL Connection not available.
ERROR:Frugally:Exception on / [GET]
Traceback (most recent call last):
  File "/usr/local/lib/python3.6/dist-packages/flask/app.py", line 2447, in wsgi_app
    response = self.full_dispatch_request()
  File "/usr/local/lib/python3.6/dist-packages/flask/app.py", line 1952, in full_dispatch_request
    rv = self.handle_user_exception(e)
  File "/usr/local/lib/python3.6/dist-packages/flask/app.py", line 1821, in handle_user_exception
    reraise(exc_type, exc_value, tb)
  File "/usr/local/lib/python3.6/dist-packages/flask/_compat.py", line 39, in reraise
    raise value
  File "/usr/local/lib/python3.6/dist-packages/flask/app.py", line 1950, in full_dispatch_request
    rv = self.dispatch_request()
  File "/usr/local/lib/python3.6/dist-packages/flask/app.py", line 1936, in dispatch_request
    return self.view_functions[rule.endpoint](**req.view_args)
  File "/var/www/Frugally/Frugally/__init__.py", line 56, in index
    nordstrom = getSQLNordstrom()
  File "/var/www/Frugally/Frugally/__init__.py", line 490, in getSQLNordstrom
    cursor = conn.cursor()
  File "/usr/local/lib/python3.6/dist-packages/mysql/connector/connection_cext.py", line 541, in cursor
    raise errors.OperationalError("MySQL Connection not available.")
mysql.connector.errors.OperationalError: MySQL Connection not available.
ERROR:Frugally:Exception on / [GET]
Traceback (most recent call last):
  File "/usr/local/lib/python3.6/dist-packages/flask/app.py", line 2447, in wsgi_app
    response = self.full_dispatch_request()
  File "/usr/local/lib/python3.6/dist-packages/flask/app.py", line 1952, in full_dispatch_request
    rv = self.handle_user_exception(e)
  File "/usr/local/lib/python3.6/dist-packages/flask/app.py", line 1821, in handle_user_exception
    reraise(exc_type, exc_value, tb)
  File "/usr/local/lib/python3.6/dist-packages/flask/_compat.py", line 39, in reraise
    raise value
  File "/usr/local/lib/python3.6/dist-packages/flask/app.py", line 1950, in full_dispatch_request
    rv = self.dispatch_request()
  File "/usr/local/lib/python3.6/dist-packages/flask/app.py", line 1936, in dispatch_request
    return self.view_functions[rule.endpoint](**req.view_args)
  File "/var/www/Frugally/Frugally/__init__.py", line 56, in index
    nordstrom = getSQLNordstrom()
  File "/var/www/Frugally/Frugally/__init__.py", line 490, in getSQLNordstrom
    cursor = conn.cursor()
  File "/usr/local/lib/python3.6/dist-packages/mysql/connector/connection_cext.py", line 541, in cursor
    raise errors.OperationalError("MySQL Connection not available.")
mysql.connector.errors.OperationalError: MySQL Connection not available.
ERROR:Frugally:Exception on / [GET]
Traceback (most recent call last):
  File "/usr/local/lib/python3.6/dist-packages/flask/app.py", line 2447, in wsgi_app
    response = self.full_dispatch_request()
  File "/usr/local/lib/python3.6/dist-packages/flask/app.py", line 1952, in full_dispatch_request
    rv = self.handle_user_exception(e)
  File "/usr/local/lib/python3.6/dist-packages/flask/app.py", line 1821, in handle_user_exception
    reraise(exc_type, exc_value, tb)
  File "/usr/local/lib/python3.6/dist-packages/flask/_compat.py", line 39, in reraise
    raise value
  File "/usr/local/lib/python3.6/dist-packages/flask/app.py", line 1950, in full_dispatch_request
    rv = self.dispatch_request()
  File "/usr/local/lib/python3.6/dist-packages/flask/app.py", line 1936, in dispatch_request
    return self.view_functions[rule.endpoint](**req.view_args)
  File "/var/www/Frugally/Frugally/__init__.py", line 56, in index
    nordstrom = getSQLNordstrom()
  File "/var/www/Frugally/Frugally/__init__.py", line 490, in getSQLNordstrom
    cursor = conn.cursor()
  File "/usr/local/lib/python3.6/dist-packages/mysql/connector/connection_cext.py", line 541, in cursor
    raise errors.OperationalError("MySQL Connection not available.")
mysql.connector.errors.OperationalError: MySQL Connection not available.
ERROR:Frugally:Exception on / [GET]
Traceback (most recent call last):
  File "/usr/local/lib/python3.6/dist-packages/flask/app.py", line 2447, in wsgi_app
    response = self.full_dispatch_request()
  File "/usr/local/lib/python3.6/dist-packages/flask/app.py", line 1952, in full_dispatch_request
    rv = self.handle_user_exception(e)
  File "/usr/local/lib/python3.6/dist-packages/flask/app.py", line 1821, in handle_user_exception
    reraise(exc_type, exc_value, tb)
  File "/usr/local/lib/python3.6/dist-packages/flask/_compat.py", line 39, in reraise
    raise value
  File "/usr/local/lib/python3.6/dist-packages/flask/app.py", line 1950, in full_dispatch_request
    rv = self.dispatch_request()
  File "/usr/local/lib/python3.6/dist-packages/flask/app.py", line 1936, in dispatch_request
    return self.view_functions[rule.endpoint](**req.view_args)
  File "/var/www/Frugally/Frugally/__init__.py", line 56, in index
    nordstrom = getSQLNordstrom()
  File "/var/www/Frugally/Frugally/__init__.py", line 490, in getSQLNordstrom
    cursor = conn.cursor()
  File "/usr/local/lib/python3.6/dist-packages/mysql/connector/connection_cext.py", line 541, in cursor
    raise errors.OperationalError("MySQL Connection not available.")
mysql.connector.errors.OperationalError: MySQL Connection not available.
ERROR:Frugally:Exception on / [GET]
Traceback (most recent call last):
  File "/usr/local/lib/python3.6/dist-packages/flask/app.py", line 2447, in wsgi_app
    response = self.full_dispatch_request()
  File "/usr/local/lib/python3.6/dist-packages/flask/app.py", line 1952, in full_dispatch_request
    rv = self.handle_user_exception(e)
  File "/usr/local/lib/python3.6/dist-packages/flask/app.py", line 1821, in handle_user_exception
    reraise(exc_type, exc_value, tb)
  File "/usr/local/lib/python3.6/dist-packages/flask/_compat.py", line 39, in reraise
    raise value
  File "/usr/local/lib/python3.6/dist-packages/flask/app.py", line 1950, in full_dispatch_request
    rv = self.dispatch_request()
  File "/usr/local/lib/python3.6/dist-packages/flask/app.py", line 1936, in dispatch_request
    return self.view_functions[rule.endpoint](**req.view_args)
  File "/var/www/Frugally/Frugally/__init__.py", line 56, in index
    nordstrom = getSQLNordstrom()
  File "/var/www/Frugally/Frugally/__init__.py", line 490, in getSQLNordstrom
    cursor = conn.cursor()
  File "/usr/local/lib/python3.6/dist-packages/mysql/connector/connection_cext.py", line 541, in cursor
    raise errors.OperationalError("MySQL Connection not available.")
mysql.connector.errors.OperationalError: MySQL Connection not available.
ERROR:Frugally:Exception on / [GET]
Traceback (most recent call last):
  File "/usr/local/lib/python3.6/dist-packages/flask/app.py", line 2447, in wsgi_app
    response = self.full_dispatch_request()
  File "/usr/local/lib/python3.6/dist-packages/flask/app.py", line 1952, in full_dispatch_request
    rv = self.handle_user_exception(e)
  File "/usr/local/lib/python3.6/dist-packages/flask/app.py", line 1821, in handle_user_exception
    reraise(exc_type, exc_value, tb)
  File "/usr/local/lib/python3.6/dist-packages/flask/_compat.py", line 39, in reraise
    raise value
  File "/usr/local/lib/python3.6/dist-packages/flask/app.py", line 1950, in full_dispatch_request
    rv = self.dispatch_request()
  File "/usr/local/lib/python3.6/dist-packages/flask/app.py", line 1936, in dispatch_request
    return self.view_functions[rule.endpoint](**req.view_args)
  File "/var/www/Frugally/Frugally/__init__.py", line 56, in index
    nordstrom = getSQLNordstrom()
  File "/var/www/Frugally/Frugally/__init__.py", line 490, in getSQLNordstrom
    cursor = conn.cursor()
  File "/usr/local/lib/python3.6/dist-packages/mysql/connector/connection_cext.py", line 541, in cursor
    raise errors.OperationalError("MySQL Connection not available.")
mysql.connector.errors.OperationalError: MySQL Connection not available.
ERROR:Frugally:Exception on / [GET]
Traceback (most recent call last):
  File "/usr/local/lib/python3.6/dist-packages/flask/app.py", line 2447, in wsgi_app
    response = self.full_dispatch_request()
  File "/usr/local/lib/python3.6/dist-packages/flask/app.py", line 1952, in full_dispatch_request
    rv = self.handle_user_exception(e)
  File "/usr/local/lib/python3.6/dist-packages/flask/app.py", line 1821, in handle_user_exception
    reraise(exc_type, exc_value, tb)
  File "/usr/local/lib/python3.6/dist-packages/flask/_compat.py", line 39, in reraise
    raise value
  File "/usr/local/lib/python3.6/dist-packages/flask/app.py", line 1950, in full_dispatch_request
    rv = self.dispatch_request()
  File "/usr/local/lib/python3.6/dist-packages/flask/app.py", line 1936, in dispatch_request
    return self.view_functions[rule.endpoint](**req.view_args)
  File "/var/www/Frugally/Frugally/__init__.py", line 56, in index
    nordstrom = getSQLNordstrom()
  File "/var/www/Frugally/Frugally/__init__.py", line 490, in getSQLNordstrom
    cursor = conn.cursor()
  File "/usr/local/lib/python3.6/dist-packages/mysql/connector/connection_cext.py", line 541, in cursor
    raise errors.OperationalError("MySQL Connection not available.")
mysql.connector.errors.OperationalError: MySQL Connection not available.
ERROR:Frugally:Exception on / [GET]
Traceback (most recent call last):
  File "/usr/local/lib/python3.6/dist-packages/flask/app.py", line 2447, in wsgi_app
    response = self.full_dispatch_request()
  File "/usr/local/lib/python3.6/dist-packages/flask/app.py", line 1952, in full_dispatch_request
    rv = self.handle_user_exception(e)
  File "/usr/local/lib/python3.6/dist-packages/flask/app.py", line 1821, in handle_user_exception
    reraise(exc_type, exc_value, tb)
  File "/usr/local/lib/python3.6/dist-packages/flask/_compat.py", line 39, in reraise
    raise value
  File "/usr/local/lib/python3.6/dist-packages/flask/app.py", line 1950, in full_dispatch_request
    rv = self.dispatch_request()
  File "/usr/local/lib/python3.6/dist-packages/flask/app.py", line 1936, in dispatch_request
    return self.view_functions[rule.endpoint](**req.view_args)
  File "/var/www/Frugally/Frugally/__init__.py", line 56, in index
    nordstrom = getSQLNordstrom()
  File "/var/www/Frugally/Frugally/__init__.py", line 490, in getSQLNordstrom
    cursor = conn.cursor()
  File "/usr/local/lib/python3.6/dist-packages/mysql/connector/connection_cext.py", line 541, in cursor
    raise errors.OperationalError("MySQL Connection not available.")
mysql.connector.errors.OperationalError: MySQL Connection not available.
ERROR:Frugally:Exception on / [GET]
Traceback (most recent call last):
  File "/usr/local/lib/python3.6/dist-packages/flask/app.py", line 2447, in wsgi_app
    response = self.full_dispatch_request()
  File "/usr/local/lib/python3.6/dist-packages/flask/app.py", line 1952, in full_dispatch_request
    rv = self.handle_user_exception(e)
  File "/usr/local/lib/python3.6/dist-packages/flask/app.py", line 1821, in handle_user_exception
    reraise(exc_type, exc_value, tb)
  File "/usr/local/lib/python3.6/dist-packages/flask/_compat.py", line 39, in reraise
    raise value
  File "/usr/local/lib/python3.6/dist-packages/flask/app.py", line 1950, in full_dispatch_request
    rv = self.dispatch_request()
  File "/usr/local/lib/python3.6/dist-packages/flask/app.py", line 1936, in dispatch_request
    return self.view_functions[rule.endpoint](**req.view_args)
  File "/var/www/Frugally/Frugally/__init__.py", line 56, in index
    nordstrom = getSQLNordstrom()
  File "/var/www/Frugally/Frugally/__init__.py", line 490, in getSQLNordstrom
    cursor = conn.cursor()
  File "/usr/local/lib/python3.6/dist-packages/mysql/connector/connection_cext.py", line 541, in cursor
    raise errors.OperationalError("MySQL Connection not available.")
mysql.connector.errors.OperationalError: MySQL Connection not available.
ERROR:Frugally:Exception on / [GET]
Traceback (most recent call last):
  File "/usr/local/lib/python3.6/dist-packages/flask/app.py", line 2447, in wsgi_app
    response = self.full_dispatch_request()
  File "/usr/local/lib/python3.6/dist-packages/flask/app.py", line 1952, in full_dispatch_request
    rv = self.handle_user_exception(e)
  File "/usr/local/lib/python3.6/dist-packages/flask/app.py", line 1821, in handle_user_exception
    reraise(exc_type, exc_value, tb)
  File "/usr/local/lib/python3.6/dist-packages/flask/_compat.py", line 39, in reraise
    raise value
  File "/usr/local/lib/python3.6/dist-packages/flask/app.py", line 1950, in full_dispatch_request
    rv = self.dispatch_request()
  File "/usr/local/lib/python3.6/dist-packages/flask/app.py", line 1936, in dispatch_request
    return self.view_functions[rule.endpoint](**req.view_args)
  File "/var/www/Frugally/Frugally/__init__.py", line 56, in index
    nordstrom = getSQLNordstrom()
  File "/var/www/Frugally/Frugally/__init__.py", line 490, in getSQLNordstrom
    cursor = conn.cursor()
  File "/usr/local/lib/python3.6/dist-packages/mysql/connector/connection_cext.py", line 541, in cursor
    raise errors.OperationalError("MySQL Connection not available.")
mysql.connector.errors.OperationalError: MySQL Connection not available.
ERROR:Frugally:Exception on /men/home [GET]
Traceback (most recent call last):
  File "/usr/local/lib/python3.6/dist-packages/flask/app.py", line 2447, in wsgi_app
    response = self.full_dispatch_request()
  File "/usr/local/lib/python3.6/dist-packages/flask/app.py", line 1952, in full_dispatch_request
    rv = self.handle_user_exception(e)
  File "/usr/local/lib/python3.6/dist-packages/flask/app.py", line 1821, in handle_user_exception
    reraise(exc_type, exc_value, tb)
  File "/usr/local/lib/python3.6/dist-packages/flask/_compat.py", line 39, in reraise
    raise value
  File "/usr/local/lib/python3.6/dist-packages/flask/app.py", line 1950, in full_dispatch_request
    rv = self.dispatch_request()
  File "/usr/local/lib/python3.6/dist-packages/flask/app.py", line 1936, in dispatch_request
    return self.view_functions[rule.endpoint](**req.view_args)
  File "/var/www/Frugally/Frugally/__init__.py", line 175, in men
    items = len(objects)
NameError: name 'objects' is not defined
ERROR:Frugally:Exception on / [GET]
Traceback (most recent call last):
  File "/usr/local/lib/python3.6/dist-packages/flask/app.py", line 2447, in wsgi_app
    response = self.full_dispatch_request()
  File "/usr/local/lib/python3.6/dist-packages/flask/app.py", line 1952, in full_dispatch_request
    rv = self.handle_user_exception(e)
  File "/usr/local/lib/python3.6/dist-packages/flask/app.py", line 1821, in handle_user_exception
    reraise(exc_type, exc_value, tb)
  File "/usr/local/lib/python3.6/dist-packages/flask/_compat.py", line 39, in reraise
    raise value
  File "/usr/local/lib/python3.6/dist-packages/flask/app.py", line 1950, in full_dispatch_request
    rv = self.dispatch_request()
  File "/usr/local/lib/python3.6/dist-packages/flask/app.py", line 1936, in dispatch_request
    return self.view_functions[rule.endpoint](**req.view_args)
  File "/var/www/Frugally/Frugally/__init__.py", line 56, in index
    nordstrom = getSQLNordstrom()
  File "/var/www/Frugally/Frugally/__init__.py", line 490, in getSQLNordstrom
    cursor = conn.cursor()
  File "/usr/local/lib/python3.6/dist-packages/mysql/connector/connection_cext.py", line 541, in cursor
    raise errors.OperationalError("MySQL Connection not available.")
mysql.connector.errors.OperationalError: MySQL Connection not available.
ERROR:Frugally:Exception on / [GET]
Traceback (most recent call last):
  File "/usr/local/lib/python3.6/dist-packages/mysql/connector/connection_cext.py", line 318, in get_rows
    else self._cmysql.fetch_row()
_mysql_connector.MySQLInterfaceError: Commands out of sync; you can't run this command now

During handling of the above exception, another exception occurred:

Traceback (most recent call last):
  File "/usr/local/lib/python3.6/dist-packages/flask/app.py", line 2447, in wsgi_app
    response = self.full_dispatch_request()
  File "/usr/local/lib/python3.6/dist-packages/flask/app.py", line 1952, in full_dispatch_request
    rv = self.handle_user_exception(e)
  File "/usr/local/lib/python3.6/dist-packages/flask/app.py", line 1821, in handle_user_exception
    reraise(exc_type, exc_value, tb)
  File "/usr/local/lib/python3.6/dist-packages/flask/_compat.py", line 39, in reraise
    raise value
  File "/usr/local/lib/python3.6/dist-packages/flask/app.py", line 1950, in full_dispatch_request
    rv = self.dispatch_request()
  File "/usr/local/lib/python3.6/dist-packages/flask/app.py", line 1936, in dispatch_request
    return self.view_functions[rule.endpoint](**req.view_args)
  File "/var/www/Frugally/Frugally/__init__.py", line 56, in index
    nordstrom = getSQLNordstrom()
  File "/var/www/Frugally/Frugally/__init__.py", line 493, in getSQLNordstrom
    item = cursor.fetchall()
  File "/usr/local/lib/python3.6/dist-packages/mysql/connector/cursor_cext.py", line 490, in fetchall
    rows = self._cnx.get_rows()
  File "/usr/local/lib/python3.6/dist-packages/mysql/connector/connection_cext.py", line 349, in get_rows
    sqlstate=exc.sqlstate)
mysql.connector.errors.DatabaseError: 2014 (HY000): Commands out of sync; you can't run this command now
ERROR:Frugally:Exception on / [GET]
Traceback (most recent call last):
  File "/usr/local/lib/python3.6/dist-packages/flask/app.py", line 2447, in wsgi_app
    response = self.full_dispatch_request()
  File "/usr/local/lib/python3.6/dist-packages/flask/app.py", line 1952, in full_dispatch_request
    rv = self.handle_user_exception(e)
  File "/usr/local/lib/python3.6/dist-packages/flask/app.py", line 1821, in handle_user_exception
    reraise(exc_type, exc_value, tb)
  File "/usr/local/lib/python3.6/dist-packages/flask/_compat.py", line 39, in reraise
    raise value
  File "/usr/local/lib/python3.6/dist-packages/flask/app.py", line 1950, in full_dispatch_request
    rv = self.dispatch_request()
  File "/usr/local/lib/python3.6/dist-packages/flask/app.py", line 1936, in dispatch_request
    return self.view_functions[rule.endpoint](**req.view_args)
  File "/var/www/Frugally/Frugally/__init__.py", line 56, in index
    nordstrom = getSQLNordstrom()
  File "/var/www/Frugally/Frugally/__init__.py", line 490, in getSQLNordstrom
    cursor = conn.cursor()
  File "/usr/local/lib/python3.6/dist-packages/mysql/connector/connection_cext.py", line 541, in cursor
    raise errors.OperationalError("MySQL Connection not available.")
mysql.connector.errors.OperationalError: MySQL Connection not available.
ERROR:Frugally:Exception on / [GET]
Traceback (most recent call last):
  File "/usr/local/lib/python3.6/dist-packages/mysql/connector/connection_cext.py", line 318, in get_rows
    else self._cmysql.fetch_row()
_mysql_connector.MySQLInterfaceError: Commands out of sync; you can't run this command now

During handling of the above exception, another exception occurred:

Traceback (most recent call last):
  File "/usr/local/lib/python3.6/dist-packages/flask/app.py", line 2447, in wsgi_app
    response = self.full_dispatch_request()
  File "/usr/local/lib/python3.6/dist-packages/flask/app.py", line 1952, in full_dispatch_request
    rv = self.handle_user_exception(e)
  File "/usr/local/lib/python3.6/dist-packages/flask/app.py", line 1821, in handle_user_exception
    reraise(exc_type, exc_value, tb)
  File "/usr/local/lib/python3.6/dist-packages/flask/_compat.py", line 39, in reraise
    raise value
  File "/usr/local/lib/python3.6/dist-packages/flask/app.py", line 1950, in full_dispatch_request
    rv = self.dispatch_request()
  File "/usr/local/lib/python3.6/dist-packages/flask/app.py", line 1936, in dispatch_request
    return self.view_functions[rule.endpoint](**req.view_args)
  File "/var/www/Frugally/Frugally/__init__.py", line 56, in index
    nordstrom = getSQLNordstrom()
  File "/var/www/Frugally/Frugally/__init__.py", line 493, in getSQLNordstrom
    item = cursor.fetchall()
  File "/usr/local/lib/python3.6/dist-packages/mysql/connector/cursor_cext.py", line 490, in fetchall
    rows = self._cnx.get_rows()
  File "/usr/local/lib/python3.6/dist-packages/mysql/connector/connection_cext.py", line 349, in get_rows
    sqlstate=exc.sqlstate)
mysql.connector.errors.DatabaseError: 2014 (HY000): Commands out of sync; you can't run this command now
ERROR:Frugally:Exception on / [GET]
Traceback (most recent call last):
  File "/usr/local/lib/python3.6/dist-packages/flask/app.py", line 2447, in wsgi_app
    response = self.full_dispatch_request()
  File "/usr/local/lib/python3.6/dist-packages/flask/app.py", line 1952, in full_dispatch_request
    rv = self.handle_user_exception(e)
  File "/usr/local/lib/python3.6/dist-packages/flask/app.py", line 1821, in handle_user_exception
    reraise(exc_type, exc_value, tb)
  File "/usr/local/lib/python3.6/dist-packages/flask/_compat.py", line 39, in reraise
    raise value
  File "/usr/local/lib/python3.6/dist-packages/flask/app.py", line 1950, in full_dispatch_request
    rv = self.dispatch_request()
  File "/usr/local/lib/python3.6/dist-packages/flask/app.py", line 1936, in dispatch_request
    return self.view_functions[rule.endpoint](**req.view_args)
  File "/var/www/Frugally/Frugally/__init__.py", line 56, in index
    nordstrom = getSQLNordstrom()
  File "/var/www/Frugally/Frugally/__init__.py", line 490, in getSQLNordstrom
    cursor = conn.cursor()
  File "/usr/local/lib/python3.6/dist-packages/mysql/connector/connection_cext.py", line 541, in cursor
    raise errors.OperationalError("MySQL Connection not available.")
mysql.connector.errors.OperationalError: MySQL Connection not available.
ERROR:Frugally:Exception on / [GET]
Traceback (most recent call last):
  File "/usr/local/lib/python3.6/dist-packages/mysql/connector/connection_cext.py", line 318, in get_rows
    else self._cmysql.fetch_row()
_mysql_connector.MySQLInterfaceError: Commands out of sync; you can't run this command now

During handling of the above exception, another exception occurred:

Traceback (most recent call last):
  File "/usr/local/lib/python3.6/dist-packages/flask/app.py", line 2447, in wsgi_app
    response = self.full_dispatch_request()
  File "/usr/local/lib/python3.6/dist-packages/flask/app.py", line 1952, in full_dispatch_request
    rv = self.handle_user_exception(e)
  File "/usr/local/lib/python3.6/dist-packages/flask/app.py", line 1821, in handle_user_exception
    reraise(exc_type, exc_value, tb)
  File "/usr/local/lib/python3.6/dist-packages/flask/_compat.py", line 39, in reraise
    raise value
  File "/usr/local/lib/python3.6/dist-packages/flask/app.py", line 1950, in full_dispatch_request
    rv = self.dispatch_request()
  File "/usr/local/lib/python3.6/dist-packages/flask/app.py", line 1936, in dispatch_request
    return self.view_functions[rule.endpoint](**req.view_args)
  File "/var/www/Frugally/Frugally/__init__.py", line 56, in index
    nordstrom = getSQLNordstrom()
  File "/var/www/Frugally/Frugally/__init__.py", line 493, in getSQLNordstrom
    item = cursor.fetchall()
  File "/usr/local/lib/python3.6/dist-packages/mysql/connector/cursor_cext.py", line 490, in fetchall
    rows = self._cnx.get_rows()
  File "/usr/local/lib/python3.6/dist-packages/mysql/connector/connection_cext.py", line 349, in get_rows
    sqlstate=exc.sqlstate)
mysql.connector.errors.DatabaseError: 2014 (HY000): Commands out of sync; you can't run this command now
ERROR:Frugally:Exception on / [GET]
Traceback (most recent call last):
  File "/usr/local/lib/python3.6/dist-packages/flask/app.py", line 2447, in wsgi_app
    response = self.full_dispatch_request()
  File "/usr/local/lib/python3.6/dist-packages/flask/app.py", line 1952, in full_dispatch_request
    rv = self.handle_user_exception(e)
  File "/usr/local/lib/python3.6/dist-packages/flask/app.py", line 1821, in handle_user_exception
    reraise(exc_type, exc_value, tb)
  File "/usr/local/lib/python3.6/dist-packages/flask/_compat.py", line 39, in reraise
    raise value
  File "/usr/local/lib/python3.6/dist-packages/flask/app.py", line 1950, in full_dispatch_request
    rv = self.dispatch_request()
  File "/usr/local/lib/python3.6/dist-packages/flask/app.py", line 1936, in dispatch_request
    return self.view_functions[rule.endpoint](**req.view_args)
  File "/var/www/Frugally/Frugally/__init__.py", line 56, in index
    nordstrom = getSQLNordstrom()
  File "/var/www/Frugally/Frugally/__init__.py", line 490, in getSQLNordstrom
    cursor = conn.cursor()
  File "/usr/local/lib/python3.6/dist-packages/mysql/connector/connection_cext.py", line 541, in cursor
    raise errors.OperationalError("MySQL Connection not available.")
mysql.connector.errors.OperationalError: MySQL Connection not available.
ERROR:Frugally:Exception on / [GET]
Traceback (most recent call last):
  File "/usr/local/lib/python3.6/dist-packages/mysql/connector/connection_cext.py", line 318, in get_rows
    else self._cmysql.fetch_row()
_mysql_connector.MySQLInterfaceError: Commands out of sync; you can't run this command now

During handling of the above exception, another exception occurred:

Traceback (most recent call last):
  File "/usr/local/lib/python3.6/dist-packages/flask/app.py", line 2447, in wsgi_app
    response = self.full_dispatch_request()
  File "/usr/local/lib/python3.6/dist-packages/flask/app.py", line 1952, in full_dispatch_request
    rv = self.handle_user_exception(e)
  File "/usr/local/lib/python3.6/dist-packages/flask/app.py", line 1821, in handle_user_exception
    reraise(exc_type, exc_value, tb)
  File "/usr/local/lib/python3.6/dist-packages/flask/_compat.py", line 39, in reraise
    raise value
  File "/usr/local/lib/python3.6/dist-packages/flask/app.py", line 1950, in full_dispatch_request
    rv = self.dispatch_request()
  File "/usr/local/lib/python3.6/dist-packages/flask/app.py", line 1936, in dispatch_request
    return self.view_functions[rule.endpoint](**req.view_args)
  File "/var/www/Frugally/Frugally/__init__.py", line 56, in index
    nordstrom = getSQLNordstrom()
  File "/var/www/Frugally/Frugally/__init__.py", line 493, in getSQLNordstrom
    item = cursor.fetchall()
  File "/usr/local/lib/python3.6/dist-packages/mysql/connector/cursor_cext.py", line 490, in fetchall
    rows = self._cnx.get_rows()
  File "/usr/local/lib/python3.6/dist-packages/mysql/connector/connection_cext.py", line 349, in get_rows
    sqlstate=exc.sqlstate)
mysql.connector.errors.DatabaseError: 2014 (HY000): Commands out of sync; you can't run this command now
ERROR:Frugally:Exception on / [GET]
Traceback (most recent call last):
  File "/usr/local/lib/python3.6/dist-packages/flask/app.py", line 2447, in wsgi_app
    response = self.full_dispatch_request()
  File "/usr/local/lib/python3.6/dist-packages/flask/app.py", line 1952, in full_dispatch_request
    rv = self.handle_user_exception(e)
  File "/usr/local/lib/python3.6/dist-packages/flask/app.py", line 1821, in handle_user_exception
    reraise(exc_type, exc_value, tb)
  File "/usr/local/lib/python3.6/dist-packages/flask/_compat.py", line 39, in reraise
    raise value
  File "/usr/local/lib/python3.6/dist-packages/flask/app.py", line 1950, in full_dispatch_request
    rv = self.dispatch_request()
  File "/usr/local/lib/python3.6/dist-packages/flask/app.py", line 1936, in dispatch_request
    return self.view_functions[rule.endpoint](**req.view_args)
  File "/var/www/Frugally/Frugally/__init__.py", line 56, in index
    nordstrom = getSQLNordstrom()
  File "/var/www/Frugally/Frugally/__init__.py", line 490, in getSQLNordstrom
    cursor = conn.cursor()
  File "/usr/local/lib/python3.6/dist-packages/mysql/connector/connection_cext.py", line 539, in cursor
    self.handle_unread_result(prepared)
  File "/usr/local/lib/python3.6/dist-packages/mysql/connector/connection_cext.py", line 712, in handle_unread_result
    raise errors.InternalError("Unread result found")
mysql.connector.errors.InternalError: Unread result found
ERROR:Frugally:Exception on / [GET]
Traceback (most recent call last):
  File "/usr/local/lib/python3.6/dist-packages/flask/app.py", line 2447, in wsgi_app
    response = self.full_dispatch_request()
  File "/usr/local/lib/python3.6/dist-packages/flask/app.py", line 1952, in full_dispatch_request
    rv = self.handle_user_exception(e)
  File "/usr/local/lib/python3.6/dist-packages/flask/app.py", line 1821, in handle_user_exception
    reraise(exc_type, exc_value, tb)
  File "/usr/local/lib/python3.6/dist-packages/flask/_compat.py", line 39, in reraise
    raise value
  File "/usr/local/lib/python3.6/dist-packages/flask/app.py", line 1950, in full_dispatch_request
    rv = self.dispatch_request()
  File "/usr/local/lib/python3.6/dist-packages/flask/app.py", line 1936, in dispatch_request
    return self.view_functions[rule.endpoint](**req.view_args)
  File "/var/www/Frugally/Frugally/__init__.py", line 56, in index
    nordstrom = getSQLNordstrom()
  File "/var/www/Frugally/Frugally/__init__.py", line 490, in getSQLNordstrom
    cursor = conn.cursor()
  File "/usr/local/lib/python3.6/dist-packages/mysql/connector/connection_cext.py", line 541, in cursor
    raise errors.OperationalError("MySQL Connection not available.")
mysql.connector.errors.OperationalError: MySQL Connection not available.
ERROR:Frugally:Exception on / [GET]
Traceback (most recent call last):
  File "/usr/local/lib/python3.6/dist-packages/mysql/connector/connection_cext.py", line 318, in get_rows
    else self._cmysql.fetch_row()
_mysql_connector.MySQLInterfaceError: Commands out of sync; you can't run this command now

During handling of the above exception, another exception occurred:

Traceback (most recent call last):
  File "/usr/local/lib/python3.6/dist-packages/flask/app.py", line 2447, in wsgi_app
    response = self.full_dispatch_request()
  File "/usr/local/lib/python3.6/dist-packages/flask/app.py", line 1952, in full_dispatch_request
    rv = self.handle_user_exception(e)
  File "/usr/local/lib/python3.6/dist-packages/flask/app.py", line 1821, in handle_user_exception
    reraise(exc_type, exc_value, tb)
  File "/usr/local/lib/python3.6/dist-packages/flask/_compat.py", line 39, in reraise
    raise value
  File "/usr/local/lib/python3.6/dist-packages/flask/app.py", line 1950, in full_dispatch_request
    rv = self.dispatch_request()
  File "/usr/local/lib/python3.6/dist-packages/flask/app.py", line 1936, in dispatch_request
    return self.view_functions[rule.endpoint](**req.view_args)
  File "/var/www/Frugally/Frugally/__init__.py", line 56, in index
    nordstrom = getSQLNordstrom()
  File "/var/www/Frugally/Frugally/__init__.py", line 493, in getSQLNordstrom
    item = cursor.fetchall()
  File "/usr/local/lib/python3.6/dist-packages/mysql/connector/cursor_cext.py", line 490, in fetchall
    rows = self._cnx.get_rows()
  File "/usr/local/lib/python3.6/dist-packages/mysql/connector/connection_cext.py", line 349, in get_rows
    sqlstate=exc.sqlstate)
mysql.connector.errors.DatabaseError: 2014 (HY000): Commands out of sync; you can't run this command now
ERROR:Frugally:Exception on / [GET]
Traceback (most recent call last):
  File "/usr/local/lib/python3.6/dist-packages/flask/app.py", line 2447, in wsgi_app
    response = self.full_dispatch_request()
  File "/usr/local/lib/python3.6/dist-packages/flask/app.py", line 1952, in full_dispatch_request
    rv = self.handle_user_exception(e)
  File "/usr/local/lib/python3.6/dist-packages/flask/app.py", line 1821, in handle_user_exception
    reraise(exc_type, exc_value, tb)
  File "/usr/local/lib/python3.6/dist-packages/flask/_compat.py", line 39, in reraise
    raise value
  File "/usr/local/lib/python3.6/dist-packages/flask/app.py", line 1950, in full_dispatch_request
    rv = self.dispatch_request()
  File "/usr/local/lib/python3.6/dist-packages/flask/app.py", line 1936, in dispatch_request
    return self.view_functions[rule.endpoint](**req.view_args)
  File "/var/www/Frugally/Frugally/__init__.py", line 56, in index
    nordstrom = getSQLNordstrom()
  File "/var/www/Frugally/Frugally/__init__.py", line 490, in getSQLNordstrom
    cursor = conn.cursor()
  File "/usr/local/lib/python3.6/dist-packages/mysql/connector/connection_cext.py", line 539, in cursor
    self.handle_unread_result(prepared)
  File "/usr/local/lib/python3.6/dist-packages/mysql/connector/connection_cext.py", line 712, in handle_unread_result
    raise errors.InternalError("Unread result found")
mysql.connector.errors.InternalError: Unread result found
ERROR:Frugally:Exception on / [GET]
Traceback (most recent call last):
  File "/usr/local/lib/python3.6/dist-packages/flask/app.py", line 2447, in wsgi_app
    response = self.full_dispatch_request()
  File "/usr/local/lib/python3.6/dist-packages/flask/app.py", line 1952, in full_dispatch_request
    rv = self.handle_user_exception(e)
  File "/usr/local/lib/python3.6/dist-packages/flask/app.py", line 1821, in handle_user_exception
    reraise(exc_type, exc_value, tb)
  File "/usr/local/lib/python3.6/dist-packages/flask/_compat.py", line 39, in reraise
    raise value
  File "/usr/local/lib/python3.6/dist-packages/flask/app.py", line 1950, in full_dispatch_request
    rv = self.dispatch_request()
  File "/usr/local/lib/python3.6/dist-packages/flask/app.py", line 1936, in dispatch_request
    return self.view_functions[rule.endpoint](**req.view_args)
  File "/var/www/Frugally/Frugally/__init__.py", line 56, in index
    nordstrom = getSQLNordstrom()
  File "/var/www/Frugally/Frugally/__init__.py", line 490, in getSQLNordstrom
    cursor = conn.cursor()
  File "/usr/local/lib/python3.6/dist-packages/mysql/connector/connection_cext.py", line 541, in cursor
    raise errors.OperationalError("MySQL Connection not available.")
mysql.connector.errors.OperationalError: MySQL Connection not available.
ERROR:Frugally:Exception on / [GET]
Traceback (most recent call last):
  File "/usr/local/lib/python3.6/dist-packages/mysql/connector/connection_cext.py", line 318, in get_rows
    else self._cmysql.fetch_row()
_mysql_connector.MySQLInterfaceError: Commands out of sync; you can't run this command now

During handling of the above exception, another exception occurred:

Traceback (most recent call last):
  File "/usr/local/lib/python3.6/dist-packages/flask/app.py", line 2447, in wsgi_app
    response = self.full_dispatch_request()
  File "/usr/local/lib/python3.6/dist-packages/flask/app.py", line 1952, in full_dispatch_request
    rv = self.handle_user_exception(e)
  File "/usr/local/lib/python3.6/dist-packages/flask/app.py", line 1821, in handle_user_exception
    reraise(exc_type, exc_value, tb)
  File "/usr/local/lib/python3.6/dist-packages/flask/_compat.py", line 39, in reraise
    raise value
  File "/usr/local/lib/python3.6/dist-packages/flask/app.py", line 1950, in full_dispatch_request
    rv = self.dispatch_request()
  File "/usr/local/lib/python3.6/dist-packages/flask/app.py", line 1936, in dispatch_request
    return self.view_functions[rule.endpoint](**req.view_args)
  File "/var/www/Frugally/Frugally/__init__.py", line 56, in index
    nordstrom = getSQLNordstrom()
  File "/var/www/Frugally/Frugally/__init__.py", line 493, in getSQLNordstrom
    item = cursor.fetchall()
  File "/usr/local/lib/python3.6/dist-packages/mysql/connector/cursor_cext.py", line 490, in fetchall
    rows = self._cnx.get_rows()
  File "/usr/local/lib/python3.6/dist-packages/mysql/connector/connection_cext.py", line 349, in get_rows
    sqlstate=exc.sqlstate)
mysql.connector.errors.DatabaseError: 2014 (HY000): Commands out of sync; you can't run this command now
ERROR:Frugally:Exception on /men/home [GET]
Traceback (most recent call last):
  File "/usr/local/lib/python3.6/dist-packages/flask/app.py", line 2447, in wsgi_app
    response = self.full_dispatch_request()
  File "/usr/local/lib/python3.6/dist-packages/flask/app.py", line 1952, in full_dispatch_request
    rv = self.handle_user_exception(e)
  File "/usr/local/lib/python3.6/dist-packages/flask/app.py", line 1821, in handle_user_exception
    reraise(exc_type, exc_value, tb)
  File "/usr/local/lib/python3.6/dist-packages/flask/_compat.py", line 39, in reraise
    raise value
  File "/usr/local/lib/python3.6/dist-packages/flask/app.py", line 1950, in full_dispatch_request
    rv = self.dispatch_request()
  File "/usr/local/lib/python3.6/dist-packages/flask/app.py", line 1936, in dispatch_request
    return self.view_functions[rule.endpoint](**req.view_args)
  File "/var/www/Frugally/Frugally/__init__.py", line 175, in men
    items = len(objects)
NameError: name 'objects' is not defined
